<?xml version="1.0"?>
<robot name="cart_pole" xmlns:xacro="http://wiki.ros.org/xacro">

<xacro:include filename="$(find cart_pole_description)/cart_pole/ros2_control.urdf.xacro"/> 
<link name="support_pole">
<visual>
<origin xyz="0.085000000000000019984 0.025000000000000001388 -0.019999999999999990008" rpy="0 -0 0" />
<geometry>
<mesh filename="package://cart_pole_description/cart_pole/support_plaform_1.stl"/>
</geometry>
<material name="support_plaform_1_material">
<color rgba="0.61568627450980395466 0.81176470588235294379 0.92941176470588238168 1.0"/>
</material>
</visual>
<collision>
<origin xyz="0.085000000000000019984 0.025000000000000001388 -0.019999999999999990008" rpy="0 -0 0" />
<geometry>
<mesh filename="package://cart_pole_description/cart_pole/support_plaform_1.stl"/>
</geometry>
</collision>
<inertial>
<origin xyz="0.085000000000000019984 0.0019366224157371760613 0.20527754982977566844" rpy="0 0 0"/>
<mass value="8.3650792577619803581" />
<inertia ixx="0.18809404056513884251" ixy="0"  ixz="0" iyy="0.19768960892502629445" iyz="0.0034874963072423744229" izz="0.014632587595117504606" />
</inertial>
</link>

<link name="cart_pole">
<visual>
<origin xyz="0.0050000000000000009714 -0.049999999999999988898 0" rpy="-1.570796326794896558 -1.570796326794896558 0" />
<geometry>
<mesh filename="package://cart_pole_description/cart_pole/cart_pole_line.stl"/>
</geometry>
<material name="cart_pole_line_material">
<color rgba="0.61568627450980395466 0.81176470588235294379 0.92941176470588238168 1.0"/>
</material>
</visual>
<collision>
<origin xyz="0.0050000000000000009714 -0.049999999999999988898 0" rpy="-1.570796326794896558 -1.570796326794896558 0" />
<geometry>
<mesh filename="package://cart_pole_description/cart_pole/cart_pole_line.stl"/>
</geometry>
</collision>
<inertial>
<origin xyz="-0.99507213325206489429 -0.021216690244781032104 -3.5306212902930945573e-05" rpy="0 0 0"/>
<mass value="17.129471613392958318" />
<inertia ixx="0.010371517126750266768" ixy="-2.2571194222369972551e-05"  ixz="8.5176426230256071983e-06" iyy="5.7133527876254550648" iyz="-5.938288855520099704e-06" izz="5.7091229148612372413" />
</inertial>
</link>

<link name="support_plaform_1">
<visual>
<origin xyz="0.0049999999999998934186 -0.48999999999999999112 6.9388939039072283776e-17" rpy="-1.570796326794896558 -1.570796326794896558 0" />
<geometry>
<mesh filename="package://cart_pole_description/cart_pole/support_plaform_1.stl"/>
</geometry>
<material name="support_plaform_1_material">
<color rgba="0.61568627450980395466 0.81176470588235294379 0.92941176470588238168 1.0"/>
</material>
</visual>
<collision>
<origin xyz="0.0049999999999998934186 -0.48999999999999999112 6.9388939039072283776e-17" rpy="-1.570796326794896558 -1.570796326794896558 0" />
<geometry>
<mesh filename="package://cart_pole_description/cart_pole/support_plaform_1.stl"/>
</geometry>
</collision>
<inertial>
<origin xyz="-0.018063377584262931691 -0.26472245017022433267 6.5441072379336884681e-17" rpy="0 0 0"/>
<mass value="8.3650792577619803581" />
<inertia ixx="0.19768960892502629445" ixy="0.0034874963072423744229"  ixz="0" iyy="0.014632587595117504606" iyz="0" izz="0.18809404056513884251" />
</inertial>
</link>

<joint name="fastened 3" type="fixed">
<origin xyz="-1.9900000000000002132 0 -1.3877787807814456755e-17" rpy="3.141592653589793116 -0 3.141592653589793116" />
<parent link="cart_pole" />
<child link="support_plaform_1" />
<axis xyz="0 0 1"/>
<limit effort="1" velocity="20" />
<joint_properties friction="0.0"/>
</joint>

<link name="cart_move">
<visual>
<origin xyz="0.010000000000000008882 -0.025000000000000022204 -0.075000000000000066613" rpy="-1.570796326794896558 -1.570796326794896336 0" />
<geometry>
<mesh filename="package://cart_pole_description/cart_pole/cart_move.stl"/>
</geometry>
<material name="cart_move_material">
<color rgba="0.61568627450980395466 0.81176470588235294379 0.92941176470588238168 1.0"/>
</material>
</visual>
<collision>
<origin xyz="0.010000000000000008882 -0.025000000000000022204 -0.075000000000000066613" rpy="-1.570796326794896558 -1.570796326794896336 0" />
<geometry>
<mesh filename="package://cart_pole_description/cart_pole/cart_move.stl"/>
</geometry>
</collision>
<inertial>
<origin xyz="-0.039380514238607201849 0.03507424335133896981 -5.5511151231257827021e-17" rpy="0 0 0"/>
<mass value="2.7582989593438584919" />
<inertia ixx="0.0072884337806232426735" ixy="1.7214130923659983201e-05"  ixz="5.5457548773363819873e-21" iyy="0.007943139603199119228" iyz="9.1364122808394913014e-19" izz="0.0051071794741707502926" />
</inertial>
</link>

<link name="cart_swinger">
<visual>
<origin xyz="0 -0.47999999999999998224 -0.0050000000000000044409" rpy="-1.570796326794896558 -0 0" />
<geometry>
<mesh filename="package://cart_pole_description/cart_pole/cart_swinger.stl"/>
</geometry>
<material name="cart_swinger_material">
<color rgba="0.61568627450980395466 0.81176470588235294379 0.92941176470588238168 1.0"/>
</material>
</visual>
<collision>
<origin xyz="0 -0.47999999999999998224 -0.0050000000000000044409" rpy="-1.570796326794896558 -0 0" />
<geometry>
<mesh filename="package://cart_pole_description/cart_pole/cart_swinger.stl"/>
</geometry>
</collision>
<inertial>
<origin xyz="-2.157282115343227227e-17 -0.23320688038281839338 0.0074999999999999893141" rpy="0 0 0"/>
<mass value="0.96730709424135585817" />
<inertia ixx="0.019645015474623172408" ixy="0"  ixz="6.5797313948525898238e-12" iyy="0.00011766776891047566519" iyz="0" izz="0.019666908757294859073" />
</inertial>
</link>

<joint name="continuous_revolute 1" type="continuous">
<origin xyz="0.035000000000000003331 0.024999999999999966693 0" rpy="-0 -1.570796326794896336 0" />
<parent link="cart_move" />
<child link="cart_swinger" />
<axis xyz="0 0 1"/>
<limit effort="1" velocity="20" />
<joint_properties friction="0.0"/>
</joint>

<joint name="slider_1" type="prismatic">
<origin xyz="-0.99499999999999999556 -0.024999999999999966693 0.040000000000000035527" rpy="-0 -1.570796326794896558 0" />
<parent link="cart_pole" />
<child link="cart_move" />
<axis xyz="0 0 1"/>
<limit effort="1" velocity="20" lower="-0.8499999999999999778" upper="0.8499999999999999778"/>
<joint_properties friction="0.0"/>
</joint>

<joint name="fastened 2" type="fixed">
<origin xyz="0.084999999999999964473 0.019999999999999993477 0.46999999999999997335" rpy="1.570796326794896558 -0 1.570796326794896558" />
<parent link="support_pole" />
<child link="cart_pole" />
<axis xyz="0 0 1"/>
<limit effort="1" velocity="20" />
<joint_properties friction="0.0"/>
</joint>


</robot>
